{"name": "test_login_with_password", "status": "broken", "statusDetails": {"message": "selenium.common.exceptions.WebDriverException: Message: An unknown server-side error occurred while processing the command. Original error: The process has received SIGINT signal\nStacktrace:\nUnknownError: An unknown server-side error occurred while processing the command. Original error: The process has received SIGINT signal\n    at getResponseForW3CError (/Users/lekhraj/npm-packages/lib/node_modules/appium/node_modules/@appium/base-driver/lib/protocol/errors.js:1145:9)\n    at asyncHandler (/Users/lekhraj/npm-packages/lib/node_modules/appium/node_modules/@appium/base-driver/lib/protocol/protocol.js:485:57)\n    at runNextTicks (node:internal/process/task_queues:60:5)\n    at processImmediate (node:internal/timers:449:9)", "trace": "self = <Testcases.test_E2E.TestEmbibeApp object at 0x1064d35e0>\n\n    @pytest.mark.usefixtures(\"appiumdriver\", \"log_on_failure\")\n    def test_login_with_password(self):\n>       self._login_with_password()\n\nTestcases/test_E2E.py:22: \n_ _ _ _ _ _ _ _ _ _ _ _ _ _ _ _ _ _ _ _ _ _ _ _ _ _ _ _ _ _ _ _ _ _ _ _ _ _ _ _ _ _ _ _ _ _ _ _ _ _ _ _ _ _ _ _ _ _ _ _ _ _ _ _ _ _ _ _ _ _ _ _ _ _ _ _ _ _ _ _ _ _ _ _\nTestcases/test_E2E.py:18: in _login_with_password\n    lp.signinusingpassword()\nPages/landingPages.py:34: in signinusingpassword\n    self.driver.find_element(*landingpages.stu_email_field).click()\n../../Library/Python/3.10/lib/python/site-packages/appium/webdriver/webdriver.py:382: in find_element\n    return self.execute(RemoteCommand.FIND_ELEMENT, {'using': by, 'value': value})['value']\n../../Library/Python/3.10/lib/python/site-packages/selenium/webdriver/remote/webdriver.py:380: in execute\n    self.error_handler.check_response(response)\n_ _ _ _ _ _ _ _ _ _ _ _ _ _ _ _ _ _ _ _ _ _ _ _ _ _ _ _ _ _ _ _ _ _ _ _ _ _ _ _ _ _ _ _ _ _ _ _ _ _ _ _ _ _ _ _ _ _ _ _ _ _ _ _ _ _ _ _ _ _ _ _ _ _ _ _ _ _ _ _ _ _ _ _\n\nself = <appium.webdriver.errorhandler.MobileErrorHandler object at 0x106528b80>\nresponse = {'status': 500, 'value': '{\"value\":{\"error\":\"unknown error\",\"message\":\"An unknown server-side error occurred while pro...   at runNextTicks (node:internal/process/task_queues:60:5)\\\\n    at processImmediate (node:internal/timers:449:9)\"}}'}\n\n    def check_response(self, response: Dict[str, Any]) -> None:\n        \"\"\"\n        https://www.w3.org/TR/webdriver/#errors\n        \"\"\"\n        payload = response.get('value', '')\n        if isinstance(payload, dict):\n            payload_dict = payload\n        else:\n            try:\n                payload_dict = json.loads(payload)\n            except (json.JSONDecodeError, TypeError):\n                return\n            if not isinstance(payload_dict, dict):\n                return\n        value = payload_dict.get('value')\n        if not isinstance(value, dict):\n            return\n        error = value.get('error')\n        if not error:\n            return\n    \n        message = value.get('message', error)\n        stacktrace = value.get('stacktrace', '')\n        # In theory, we should also be checking HTTP status codes.\n        # Java client, for example, prints a warning if the actual `error`\n        # value does not match to the response's HTTP status code.\n        exception_class: Type[sel_exceptions.WebDriverException] = ERROR_TO_EXC_MAPPING.get(\n            error, sel_exceptions.WebDriverException\n        )\n        if exception_class is sel_exceptions.WebDriverException and message:\n            if message == 'No such context found.':\n                exception_class = appium_exceptions.NoSuchContextException\n            elif message == 'That command could not be executed in the current context.':\n                exception_class = appium_exceptions.InvalidSwitchToTargetException\n    \n        if exception_class is sel_exceptions.UnexpectedAlertPresentException:\n            raise sel_exceptions.UnexpectedAlertPresentException(\n                msg=message,\n                stacktrace=format_stacktrace(stacktrace),\n                alert_text=value.get('data'),\n            )\n>       raise exception_class(msg=message, stacktrace=format_stacktrace(stacktrace))\nE       selenium.common.exceptions.WebDriverException: Message: An unknown server-side error occurred while processing the command. Original error: The process has received SIGINT signal\nE       Stacktrace:\nE       UnknownError: An unknown server-side error occurred while processing the command. Original error: The process has received SIGINT signal\nE           at getResponseForW3CError (/Users/lekhraj/npm-packages/lib/node_modules/appium/node_modules/@appium/base-driver/lib/protocol/errors.js:1145:9)\nE           at asyncHandler (/Users/lekhraj/npm-packages/lib/node_modules/appium/node_modules/@appium/base-driver/lib/protocol/protocol.js:485:57)\nE           at runNextTicks (node:internal/process/task_queues:60:5)\nE           at processImmediate (node:internal/timers:449:9)\n\n../../Library/Python/3.10/lib/python/site-packages/appium/webdriver/errorhandler.py:125: WebDriverException"}, "start": 1732374257273, "stop": 1732374272057, "uuid": "1d9ab58b-b17d-48ba-acc6-9e0953d5fea4", "historyId": "91161c11966ce952399f5a2bb7073cce", "testCaseId": "91161c11966ce952399f5a2bb7073cce", "fullName": "Testcases.test_E2E.TestEmbibeApp#test_login_with_password", "labels": [{"name": "tag", "value": "@pytest.mark.usefixtures('appiumdriver', 'log_on_failure')"}, {"name": "parentSuite", "value": "Testcases"}, {"name": "suite", "value": "test_E2E"}, {"name": "subSuite", "value": "TestEmbibeApp"}, {"name": "host", "value": "EBL-C02H385BQ6L4.local"}, {"name": "thread", "value": "6187-MainThread"}, {"name": "framework", "value": "pytest"}, {"name": "language", "value": "cpython3"}, {"name": "package", "value": "Testcases.test_E2E"}]}