{"uuid": "59fe91dd-efbf-42ad-b0a5-a949fabccd62", "children": ["9eb48139-163b-4d98-890c-3ba5aa445c9a"], "befores": [{"name": "log_on_failure", "status": "passed", "start": 1732374457168, "stop": 1732374457169}], "afters": [{"name": "log_on_failure::0", "status": "broken", "statusDetails": {"message": "selenium.common.exceptions.WebDriverException: Message: An unknown server-side error occurred while processing the command. Original error: Could not proxy command to the remote server. Original error: socket hang up\nStacktrace:\nUnknownError: An unknown server-side error occurred while processing the command. Original error: Could not proxy command to the remote server. Original error: socket hang up\n    at UIA2Proxy.command (/Users/lekhraj/node_modules/@appium/base-driver/lib/jsonwp-proxy/proxy.js:355:13)\n    at processTicksAndRejections (node:internal/process/task_queues:95:5)\n    at AndroidUiautomator2Driver.getScreenshot (/Users/lekhraj/.appium/node_modules/appium-uiautomator2-driver/lib/commands/screenshot.js:42:5)\n", "trace": "  File \"/Users/lekhraj/Library/Python/3.10/lib/python/site-packages/allure_commons/_allure.py\", line 221, in __call__\n    return self._fixture_function(*args, **kwargs)\n  File \"/Users/lekhraj/Library/Python/3.10/lib/python/site-packages/_pytest/fixtures.py\", line 893, in _teardown_yield_fixture\n    next(it)\n  File \"/Users/lekhraj/StudentAndroidApp/StudentAndroidApp/Testcases/conftest.py\", line 48, in log_on_failure\n    allure.attach(driver.get_screenshot_as_png(), name=\"failedtestcase\", attachment_type= AttachmentType.PNG)\n  File \"/Users/lekhraj/Library/Python/3.10/lib/python/site-packages/selenium/webdriver/remote/webdriver.py\", line 849, in get_screenshot_as_png\n    return b64decode(self.get_screenshot_as_base64().encode(\"ascii\"))\n  File \"/Users/lekhraj/Library/Python/3.10/lib/python/site-packages/selenium/webdriver/remote/webdriver.py\", line 860, in get_screenshot_as_base64\n    return self.execute(Command.SCREENSHOT)[\"value\"]\n  File \"/Users/lekhraj/Library/Python/3.10/lib/python/site-packages/selenium/webdriver/remote/webdriver.py\", line 380, in execute\n    self.error_handler.check_response(response)\n  File \"/Users/lekhraj/Library/Python/3.10/lib/python/site-packages/appium/webdriver/errorhandler.py\", line 125, in check_response\n    raise exception_class(msg=message, stacktrace=format_stacktrace(stacktrace))\n"}, "start": 1732374457266, "stop": 1732374457277}], "start": 1732374457168, "stop": 1732374457277}