{"uuid": "fdf241f4-396f-4dd7-93a8-d518f1c87a92", "children": ["36a9e449-eda6-42fc-833e-ee48cb6b9c1e"], "befores": [{"name": "appiumdriver", "status": "broken", "statusDetails": {"message": "selenium.common.exceptions.WebDriverException: Message: An unknown server-side error occurred while processing the command. Original error: Error executing adbExec. Original error: 'Command '/Users/lekhraj/Library/Android/sdk/platform-tools/adb -P 5037 -s 100ba177 shell pm clear com.embibe.student' timed out after 20000ms'. Try to increase the 20000ms adb execution timeout represented by 'adbExecTimeout' capability\nStacktrace:\nUnknownError: An unknown server-side error occurred while processing the command. Original error: Error executing adbExec. Original error: 'Command '/Users/lekhraj/Library/Android/sdk/platform-tools/adb -P 5037 -s 100ba177 shell pm clear com.embibe.student' timed out after 20000ms'. Try to increase the 20000ms adb execution timeout represented by 'adbExecTimeout' capability\n    at getResponseForW3CError (/Users/lekhraj/npm-packages/lib/node_modules/appium/node_modules/@appium/base-driver/lib/protocol/errors.js:1145:9)\n    at asyncHandler (/Users/lekhraj/npm-packages/lib/node_modules/appium/node_modules/@appium/base-driver/lib/protocol/protocol.js:485:57)\n", "trace": "  File \"/Users/lekhraj/Library/Python/3.10/lib/python/site-packages/pluggy/_callers.py\", line 167, in _multicall\n    teardown.throw(outcome._exception)\n  File \"/Users/lekhraj/Library/Python/3.10/lib/python/site-packages/_pytest/setuponly.py\", line 36, in pytest_fixture_setup\n    return (yield)\n  File \"/Users/lekhraj/Library/Python/3.10/lib/python/site-packages/pluggy/_callers.py\", line 103, in _multicall\n    res = hook_impl.function(*args)\n  File \"/Users/lekhraj/Library/Python/3.10/lib/python/site-packages/_pytest/fixtures.py\", line 1122, in pytest_fixture_setup\n    result = call_fixture_func(fixturefunc, request, kwargs)\n  File \"/Users/lekhraj/Library/Python/3.10/lib/python/site-packages/_pytest/fixtures.py\", line 877, in call_fixture_func\n    fixture_result = next(generator)\n  File \"/Users/lekhraj/StudentAndroidApp/StudentAndroidApp/Testcases/conftest.py\", line 37, in appiumdriver\n    driver = webdriver.Remote(\"http://127.0.0.1:4723\", options=option)\n  File \"/Users/lekhraj/Library/Python/3.10/lib/python/site-packages/appium/webdriver/webdriver.py\", line 229, in __init__\n    super().__init__(\n  File \"/Users/lekhraj/Library/Python/3.10/lib/python/site-packages/selenium/webdriver/remote/webdriver.py\", line 238, in __init__\n    self.start_session(capabilities)\n  File \"/Users/lekhraj/Library/Python/3.10/lib/python/site-packages/appium/webdriver/webdriver.py\", line 319, in start_session\n    response = self.execute(RemoteCommand.NEW_SESSION, w3c_caps)\n  File \"/Users/lekhraj/Library/Python/3.10/lib/python/site-packages/selenium/webdriver/remote/webdriver.py\", line 380, in execute\n    self.error_handler.check_response(response)\n  File \"/Users/lekhraj/Library/Python/3.10/lib/python/site-packages/selenium/webdriver/remote/errorhandler.py\", line 229, in check_response\n    raise exception_class(message, screen, stacktrace)\n"}, "start": 1732374587058, "stop": 1732374608259}], "start": 1732374587058, "stop": 1732374608294}